Workbook

Sheet Dashboard
C1: HDFC BANK LTD.
C8: Field | D8: Value
C9: Company | D9: HDFC Bank | U9: Metric | W9: Value
C10: Sector | D10: BFSI | U10: Intrinsic Value | W10: =DCF!D59 -> 1440.0759
C11: Analysis Period | D11: FY 2021–2025 | U11: Market Price | W11: 1002.9
C12: Currency | D12: ₹ Crore | U12: Upside Potential | W12: =(W10/W11)-1 -> 0.43591173

Sheet Sensitivity
C1: Sensitivity Analysis
D8: Ke Vs. Terminal Growth(g)
D10: =DCF!D59 -> 1440.0759 | E10: 0.02 | F10: 0.025 | G10: 0.03
D11: 0.0746 | E11: 2108.2483 | F11: 2108.2483 | G11: 2108.2483
D12: 0.0846 | E12: 1721.0657 | F12: 1721.0657 | G12: 1721.0657
D13: 0.0946 | E13: 1440.554 | F13: 1440.554 | G13: 1440.554
D14: 0.1046 | E14: 1226.6847 | F14: 1226.6847 | G14: 1226.6847
D15: 0.1146 | E15: 1057.2925 | F15: 1057.2925 | G15: 1057.2925

Sheet DCF
C1: DCF
C9: DCF Assumptions
C10: 1 | D10: Value | E10: Notes
C11: Base Year PAT (FY25) | D11: ='Raw Sheet'!I43 -> 70792.25 | E11: From P&L
C12: Forecast Horizon | D12: 5 Years | E12: FY26–FY30
C13: Method used | D13: Excess Return Model | E13: Bank-appropriate DCF
C14: Long-term growth (g) | D14: 0.025 | E14: As economy over long-term
C15: Dividend Payout | D15: 0.11 | E15: Based on historical average
C17: Growth Rate Year 1 | D17: 0.14 | E17: High growth due to momentum
C18: Growth Rate Year 2 | D18: 0.13 | E18: Slight moderation
C19: Growth Rate Year 3 | D19: 0.12 | E19: Stabilizing
C20: Growth Rate Year 4 | D20: 0.11 | E20: Converging
C21: Growth Rate Year 5 | D21: 0.1 | E21: Long-term steady growth
C23: Metric | D23: Value
C24: PAT FY21 | D24: ='Raw Sheet'!E43 -> 31833.21
C25: PAT FY25 | D25: ='Raw Sheet'!I43 -> 70792.25
C26: 5-Year PAT CAGR | D26: =(D25/D24)^(1/5) - 1 -> 0.17333238
C28: Forecast Net Profit (PAT)
C29: Year | D29: PAT (₹ Cr) | E29: Growth Rate
C30: 2025 | D30: =D11 -> 70792.25 | E30: -
C31: 2026 | D31: =D30 * (1 + E31) -> 80703.165 | E31: 0.14
C32: 2027 | D32: =D31 * (1 + E32) -> 91194.576 | E32: 0.13
C33: 2028 | D33: =D32 * (1 + E33) -> 102137.93 | E33: 0.12
C34: 2029 | D34: =D33 * (1 + E34) -> 113373.1 | E34: 0.11 | G34: Dividend Payout Ratio | I34: =D15 -> 0.11 | L34: INPUTS:
C35: 2030 | D35: =D34 * (1 + E35) -> 124710.41 | E35: 0.1 | L35: Ke | M35: =WACC!D18 -> 0.094619727
L36: WACC | M36: =WACC!D27 -> 0.077304189
L37: g | M37: =D14 -> 0.025
C38: Forecast Table | L38: BV(FY25) | M38: ='Raw Sheet'!L13+'Raw Sheet'!I10 -> 497619.44
B39: t | C39: Year | D39: Opening Book Value | E39: PAT | F39: Dividend | G39: Closing Book Value | H39: Required return | I39: Excess return | J39: PV of Excess Returns | L39: Shares outstanding | M39: ='Raw Sheet'!I23 -> 7652221674
B40: 1 | C40: 2026 | D40: =M38 -> 497619.44 | E40: =D31 -> 80703.165 | F40: =E40*$I$34 -> 8877.3482 | G40: =D40+E40-F40 -> 569445.26 | H40: =D40*$M$35 -> 47084.616 | I40: =E40-H40 -> 33618.549 | J40: =I40/(1+$M$36)^B40 -> 31206.181
B41: 2 | C41: 2027 | D41: =G40 -> 569445.26 | E41: =D32 -> 91194.576 | F41: =E41*$I$34 -> 10031.403 | G41: =D41+E41-F41 -> 650608.43 | H41: =D41*$M$35 -> 53880.755 | I41: =E41-H41 -> 37313.822 | J41: =I41/(1+$M$36)^B41 -> 32150.893
B42: 3 | C42: 2028 | D42: =G41 -> 650608.43 | E42: =D33 -> 102137.93 | F42: =E42*$I$34 -> 11235.172 | G42: =D42+E42-F42 -> 741511.19 | H42: =D42*$M$35 -> 61560.392 | I42: =E42-H42 -> 40577.534 | J42: =I42/(1+$M$36)^B42 -> 32454.177
B43: 4 | C43: 2029 | D43: =G42 -> 741511.19 | E43: =D34 -> 113373.1 | F43: =E43*$I$34 -> 12471.041 | G43: =D43+E43-F43 -> 842413.24 | H43: =D43*$M$35 -> 70161.586 | I43: =E43-H43 -> 43211.512 | J43: =I43/(1+$M$36)^B43 -> 32080.865
B44: 5 | C44: 2030 | D44: =G43 -> 842413.24 | E44: =D35 -> 124710.41 | F44: =E44*$I$34 -> 13718.145 | G44: =D44+E44-F44 -> 953405.51 | H44: =D44*$M$35 -> 79708.911 | I44: =E44-H44 -> 45001.496 | J44: =I44/(1+$M$36)^B44 -> 31012.388
C47: Terminal Value
C48: TV | D48: =I44/(M35-M37) -> 646390.02
C49: PV of TV | D49: =D48/(1+M36)^5 -> 445454.04
C52: Intrinsic Value
C53: Item | D53: Amount
C54: Opening Book Value | D54: =M38 -> 497619.44
...

Sheet Project Undertaking
C1: NPV, IRR & PI
C9: 1. PROJECT DESCRIPTION
C11: HDFC Bank plans to undertake a ₹1,200 crore Digital Lending & Analytics Infrastructure Expansion Project over 4 years.
C12: The project includes enhancing digital loan origination systems, expanding cloud-based analytics capabilities, fraud detection modernization, and establishing a secondary data center for redundancy.
C13: The project is expected to increase digital lending throughput, reduce operational costs, improve turnaround time (TAT), and enhance cross-selling capabilities.
C16: Year | D16: Description | E16: Cash Flow (₹ crore)
C17: 0 | D17: Initial Capex (hardware, software licensing, data center build) | E17: -800 | H17: 1 | I17: NPV of the Project
C18: 1 | D18: Additional Capex (cloud migration, AI scoring engine) | E18: -400
C19: 1 | D19: Operating cost savings (faster processing, automation) | E19: 120 | I19: NPV | J19: =NPV(WACC!D27,'Project Undertaking'!E39:E42)+'Project Undertaking'!E38 -> 620.21094
C20: 1 | D20: Additional digital lending revenues | E20: 180
C21: 1 | D21: Working capital (increase due to growth) | E21: -50 | H21: 2 | I21: IRR of the Project
C23: 2 | D23: Operating cost savings | E23: 200 | I23: IRR | J23: =IRR(E38:E42) -> 0.26704264
C24: 2 | D24: Digital lending uplift | E24: 260
C25: 2 | D25: Maintenance Capex | E25: -70 | H25: 3 | I25: Profitability Index
C27: 3 | D27: Operating cost savings | E27: 240 | I27: PI | J27: =(J19+(-1)*E17)/(-E17) -> 1.7752637
C28: 3 | D28: Digital lending uplift | E28: 340
C29: 3 | D29: Maintenance + AI model retraining cost | E29: -90
C31: 4 | D31: Operating cost savings | E31: 280
C32: 4 | D32: Digital lending uplift | E32: 440
C33: 4 | D33: Regulatory tech upgrade cost | E33: -100
C34: 4 | D34: Terminal benefit (efficiency + digital franchise value) | E34: 500
D37: Final Cashflows of the Project
D38: Net CF Year 0 | E38: =E17 -> -800
D39: Net CF Year 1 | E39: =SUM(E18:E21) -> -150
D40: Net CF Year 2 | E40: =SUM(E23:E25) -> 390
D41: Net CF Year 3 | E41: =SUM(E27:E29) -> 490
D42: Net CF Year 4 | E42: =SUM(E31:E34) -> 1120

Sheet WACC
C1: WACC
B8: A. | C8: Market Inputs | V8: Year | W8: Yearly Returns | X8: Market Return (Rm)
C9: Input | D9: Value | E9: Source/Note | V9: 2016 | W9: -0.088635 | X9: =1+W9 -> 0.911365 | Y9: =((PRODUCT(X9:X19))^(1/COUNT(X9:X19)))-1 -> 0.10787339
C10: Risk-Free Rate (Rf) | D10: 0.065093 | E10: India 10-year G-Sec | V10: 2017 | W10: 0.185484 | X10: =1+W10 -> 1.185484
C11: Market Return (Rm) | D11: =Y9 -> 0.10787339 | E11: Nifty50 Market Returns | V11: 2018 | W11: 0.102461 | X11: =1+W11 -> 1.102461
C12: Market Risk Premium (MRP = Rm – Rf) | D12: =D11-D10 -> 0.042780386 | E12: Auto-calc | V12: 2019 | W12: 0.143993 | X12: =1+W12 -> 1.143993
C13: Tax Rate (t) | D13: 0.2517 | E13: Effective corporate tax | V13: 2020 | W13: -0.256893 | X13: =1+W13 -> 0.743107
V14: 2021 | W14: 0.708668 | X14: =1+W14 -> 1.708668
B15: B. | C15: HDFC Bank Inputs | V15: 2022 | W15: 0.18883 | X15: =1+W15 -> 1.18883
C16: Input | D16: Value | E16: Source | V16: 2023 | W16: -0.006012 | X16: =1+W16 -> 0.993988
C17: Beta (Levered) | D17: ='BETA Calculation'!L12 -> 0.69019308 | E17: From Beta sheet | V17: 2024 | W17: 0.28613 | X17: =1+W17 -> 1.28613
C18: Cost of Equity (Ke) | D18: =D10+(D12*D17) -> 0.094619727 | E18: CAPM | V18: 2025 | W18: 0.053409 | X18: =1+W18 -> 1.053409
C19: Cost of Debt (Kd pre-tax) | D19: ='Raw Sheet'!I144 -> 0.082077208 | E19: HDFC Bank AT1/Tier2 avg rate | V19: 2026 | W19: 0.114102 | X19: =1+W19 -> 1.114102
C20: Cost of Debt (after-tax) | D20: =D19*(1-'Raw Sheet'!L18) -> 0.061418375 | E20: For WACC
C21: Market Cap (Equity Value) | D21: 1548282.3 | E21: Current | V21: g | W21: =DCF!D14 -> 0.025
C22: Total Debt (AT1 + Tier 2 + Borrowings) | D22: ='Raw Sheet'!I141 -> 547930.89 | E22: FY25 | Y22: Ke Vs. g
C23: Equity Weight (We) | D23: =1/2.09 -> 0.4784689 | E23: E / (D + E) | V23: =DCF!D59 -> 1440.0759 | W23: 0.02 | X23: 0.025 | Y23: 0.03
C24: Debt Weight (Wd) | D24: =1.09/2.09 -> 0.5215311 | E24: D / (D + E) | V24: 0.0746 | W24: 2108.2483 | X24: 2108.2483 | Y24: 2108.2483
V25: 0.0846 | W25: 1721.0657 | X25: 1721.0657 | Y25: 1721.0657
B26: C. | C26: WACC | V26: 0.0946 | W26: 1440.554 | X26: 1440.554 | Y26: 1440.554
C27: Ke*We + Wd*Kd*(1-t) | D27: =D18*D23+D20*D24 -> 0.077304189 | V27: 0.1046 | W27: 1226.6847 | X27: 1226.6847 | Y27: 1226.6847
V28: 0.1146 | W28: 1057.2925 | X28: 1057.2925 | Y28: 1057.2925

Sheet BETA Calculation
C1: Beta Calculation
D9: Date | E9: HDFC Close | F9: HDFC Weekly Return | G9: Nifty Close | H9: Nifty Weekly Return
D10: 44893 | E10: 773.28473 | G10: 18696.1 | J10: Raw Beta: | K10: β | L10: =SLOPE(F10:F166,H10:H166) -> 0.93376751
D11: 44900 | E11: 784.80872 | F11: =LN(E11/E10) -> 0.01479269 | G11: 18496.6 | H11: =LN(G11/G10) -> -0.010728015 | J11: Unlevered Beta: | K11: βu | L11: =L10/(1+(1-'Raw Sheet'!L18)*Ratios!H33) -> 0.37970608
D12: 44907 | E12: 788.94672 | F12: =LN(E12/E11) -> 0.0052587714 | G12: 18269 | H12: =LN(G12/G11) -> -0.012381276 | J12: Relevered Beta: | K12: βl | L12: =L11*(1+(1-'Raw Sheet'!L18)*Ratios!H34) -> 0.69019308
D13: 44914 | E13: 768.73767 | F13: =LN(E13/E12) -> -0.025949004 | G13: 17806.801 | H13: =LN(G13/G12) -> -0.025625184
D14: 44921 | E14: 783.41333 | F14: =LN(E14/E13) -> 0.018910656 | G14: 18105.301 | H14: =LN(G14/G13) -> 0.016624306
D15: 44928 | E15: 767.17389 | F15: =LN(E15/E14) -> -0.020946948 | G15: 17859.449 | H15: =LN(G15/G14) -> -0.01367202
D16: 44935 | E16: 770.18121 | F16: =LN(E16/E15) -> 0.0039123402 | G16: 17956.6 | H16: =LN(G16/G15) -> 0.0054249775
D17: 44942 | E17: 799.1955 | F17: =LN(E17/E16) -> 0.036979762 | G17: 18027.65 | H17: =LN(G17/G16) -> 0.0039489984
D18: 44949 | E18: 777.47089 | F18: =LN(E18/E17) -> -0.027559393 | G18: 17604.35 | H18: =LN(G18/G17) -> -0.023760704
D19: 44956 | E19: 798.16101 | F19: =LN(E19/E18) -> 0.026264147 | G19: 17854.051 | H19: =LN(G19/G18) -> 0.014084409
D20: 44963 | E20: 797.34308 | F20: =LN(E20/E19) -> -0.0010252963 | G20: 17856.5 | H20: =LN(G20/G19) -> 0.0001371706
D21: 44970 | E21: 796.76569 | F21: =LN(E21/E20) -> -0.00072440804 | G21: 17944.199 | H21: =LN(G21/G20) -> 0.0048993118
D22: 44977 | E22: 764.55151 | F22: =LN(E22/E21) -> -0.041271235 | G22: 17465.801 | H22: =LN(G22/G21) -> -0.027022172
D23: 44984 | E23: 777.51898 | F23: =LN(E23/E22) -> 0.016818653 | G23: 17594.35 | H23: =LN(G23/G22) -> 0.0073330777
D24: 44991 | E24: 764.40717 | F24: =LN(E24/E23) -> -0.017007471 | G24: 17412.9 | H24: =LN(G24/G23) -> -0.010366472
... D166: 45985 | E166: 1007.6 | F166: =LN(E166/E165) -> 0.0095231572 | G166: 26202.949 | H166: =LN(G166/G165) -> 0.0051576924

Sheet Ratios
C1: Financial Ratios
D8: ='Raw Sheet'!E9 -> 2021 | E8: ='Raw Sheet'!F9 -> 2022 | F8: ='Raw Sheet'!G9 -> 2023 | G8: ='Raw Sheet'!H9 -> 2024 | H8: ='Raw Sheet'!I9 -> 2025
C9: Profitability Ratios
C10: ='Raw Sheet'!D98 -> Net Interest Margin (NIM) | D10: ='Raw Sheet'!E98 -> 0.041 | E10: ='Raw Sheet'!F98 -> 0.04 | F10: ='Raw Sheet'!G98 -> 0.041 | G10: ='Raw Sheet'!H98 -> 0.0353 | H10: ='Raw Sheet'!I98 -> 0.0348
C11: ='Raw Sheet'!D99 -> ROA | D11: ='Raw Sheet'!E99 -> 0.0197 | E11: ='Raw Sheet'!F99 -> 0.0203 | F11: ='Raw Sheet'!G99 -> 0.0207 | G11: ='Raw Sheet'!H99 -> 0.0198 | H11: ='Raw Sheet'!I99 -> 0.0191
C12: ='Raw Sheet'!D100 -> ROE | D12: ='Raw Sheet'!E100 -> 0.1554 | E12: ='Raw Sheet'!F100 -> 0.169 | F12: ='Raw Sheet'!G100 -> 0.174 | G12: ='Raw Sheet'!H100 -> 0.1609 | H12: ='Raw Sheet'!I100 -> 0.146
C13: Efficiency Ratio | D13: =(SUM('Raw Sheet'!E34:E37)+'Raw Sheet'!E39)/'Raw Sheet'!E30 -> 0.41882952 | E13: =(SUM('Raw Sheet'!F34:F37)+'Raw Sheet'!F39)/'Raw Sheet'!F30 -> 0.42841863 | F13: =(SUM('Raw Sheet'!G34:G37)+'Raw Sheet'!G39)/'Raw Sheet'!G30 -> 0.3829354 | G13: =(SUM('Raw Sheet'!H34:H37)+'Raw Sheet'!H39)/'Raw Sheet'!H30 -> 0.62502462 | H13: =(SUM('Raw Sheet'!I34:I37)+'Raw Sheet'!I39)/'Raw Sheet'!I30 -> 0.56717644
C14: Cost/Income Ratio | D14: =('Raw Sheet'!E31+'Raw Sheet'!E32+'Raw Sheet'!E33+'Raw Sheet'!E34+'Raw Sheet'!E35+'Raw Sheet'!E36+'Raw Sheet'!E37+'Raw Sheet'!E39)/('Raw Sheet'!E30+'Raw Sheet'!E38) -> 0.34539207 | E14: =('Raw Sheet'!F31+'Raw Sheet'!F32+'Raw Sheet'!F33+'Raw Sheet'!F34+'Raw Sheet'!F35+'Raw Sheet'!F36+'Raw Sheet'!F37+'Raw Sheet'!F39)/('Raw Sheet'!F30+'Raw Sheet'!F38) -> 0.34728257 | F14: =('Raw Sheet'!G31+'Raw Sheet'!G32+'Raw Sheet'!G33+'Raw Sheet'!G34+'Raw Sheet'!G35+'Raw Sheet'!G36+'Raw Sheet'!G37+'Raw Sheet'!G39)/('Raw Sheet'!G30+'Raw Sheet'!G38) -> 0.3194851 | G14: =('Raw Sheet'!H31+'Raw Sheet'!H32+'Raw Sheet'!H33+'Raw Sheet'!H34+'Raw Sheet'!H35+'Raw Sheet'!H36+'Raw Sheet'!H37+'Raw Sheet'!H39)/('Raw Sheet'!H30+'Raw Sheet'!H38) -> 0.43453405 | H14: =('Raw Sheet'!I31+'Raw Sheet'!I32+'Raw Sheet'!I33+'Raw Sheet'!I34+'Raw Sheet'!I35+'Raw Sheet'!I36+'Raw Sheet'!I37+'Raw Sheet'!I39)/('Raw Sheet'!I30+'Raw Sheet'!I38) -> 0.40512471
C16: Capital Structure
C17: ='Raw Sheet'!D93 -> CET1 | D17: ='Raw Sheet'!E93 -> 0.1685 | E17: ='Raw Sheet'!F93 -> 0.1667 | F17: ='Raw Sheet'!G93 -> 0.164 | G17: ='Raw Sheet'!H93 -> 0.163 | H17: ='Raw Sheet'!I93 -> 0.1723
C18: ='Raw Sheet'!D94 -> Tier-1 | D18: ='Raw Sheet'!E94 -> 0.1756 | E18: ='Raw Sheet'!F94 -> 0.1787 | F18: ='Raw Sheet'!G94 -> 0.1713 | G18: ='Raw Sheet'!H94 -> 0.1679 | H18: ='Raw Sheet'!I94 -> 0.1769
C19: ='Raw Sheet'!D96 -> Leverage Ratio | D19: ='Raw Sheet'!E96 -> 0.104 | E19: ='Raw Sheet'!F96 -> 0.1062 | F19: ='Raw Sheet'!G96 -> 0.1004 | G19: ='Raw Sheet'!H96 -> 0.104 | H19: ='Raw Sheet'!I96 -> 0.1091
C20: ='Raw Sheet'!D92 -> Capital Adequecy Ratio (CAR) | D20: ='Raw Sheet'!E92 -> 0.188 | E20: ='Raw Sheet'!F92 -> 0.189 | F20: ='Raw Sheet'!G92 -> 0.193 | G20: ='Raw Sheet'!H92 -> 0.188 | H20: ='Raw Sheet'!I92 -> 0.1955
C22: Working Capital (Banking)
C23: ='Raw Sheet'!D101 -> CASA as % of total deposits | D23: ='Raw Sheet'!E101 -> 0.461 | E23: ='Raw Sheet'!F101 -> 0.482 | F23: ='Raw Sheet'!G101 -> 0.444 | G23: ='Raw Sheet'!H101 -> 0.382 | H23: ='Raw Sheet'!I101 -> 0.348
C24: AD Ratio | D24: ='Raw Sheet'!E138/'Raw Sheet'!E117 -> 0.88870432 | E24: ='Raw Sheet'!F138/'Raw Sheet'!F117 -> 0.91202793 | F24: ='Raw Sheet'!G138/'Raw Sheet'!G117 -> 0.88242222 | G24: ='Raw Sheet'!H138/'Raw Sheet'!H117 -> 1.0782025 | H24: ='Raw Sheet'!I138/'Raw Sheet'!I117 -> 0.96497007
C25: Cash to Assets | D25: ='Raw Sheet'!E27/'Raw Sheet'!E19 -> 0.054093013 | E25: ='Raw Sheet'!F27/'Raw Sheet'!F19 -> 0.061233942 | F25: ='Raw Sheet'!G27/'Raw Sheet'!G19 -> 0.046300691 | G25: ='Raw Sheet'!H27/'Raw Sheet'!H19 -> 0.044336132 | H25: ='Raw Sheet'!I27/'Raw Sheet'!I19 -> 0.032866899
C27: Dividend
C28: ='Raw Sheet'!D87 -> DPS | D28: ='Raw Sheet'!E87 -> 3.25 | E28: ='Raw Sheet'!F87 -> 7.75 | F28: ='Raw Sheet'!G87 -> 9.5 | G28: ='Raw Sheet'!H87 -> 9.75 | H28: ='Raw Sheet'!I87 -> 11
C29: ='Raw Sheet'!D89 -> EPS | D29: ='Raw Sheet'!E89 -> 56.58 | E29: ='Raw Sheet'!F89 -> 66.8 | F29: ='Raw Sheet'!G89 -> 79.25 | G29: ='Raw Sheet'!H89 -> 85.83 | H29: ='Raw Sheet'!I89 -> 88.29
C30: Dividend Payout % | D30: =D28/D29 -> 0.057440792 | E30: =E28/E29 -> 0.11601796 | F30: =F28/F29 -> 0.11987382 | G30: =G28/G29 -> 0.11359664 | H30: =H28/H29 -> 0.12458942
C31: ='Raw Sheet'!D43 -> Net Profit | D31: ='Raw Sheet'!E43 -> 31833.21 | E31: ='Raw Sheet'!F43 -> 38052.75 | F31: ='Raw Sheet'!G43 -> 45997.11 | G31: ='Raw Sheet'!H43 -> 64062.04 | H31: ='Raw Sheet'!I43 -> 70792.25
C33: D/E Ratio | D33: Industry D/E | H33: 1.95
D34: HDFC ltd. D/E | H34: ='Raw Sheet'!L15/'Raw Sheet'!L14 -> 1.0927482

Sheet Raw Sheet
C1: Financial Reports
C8: In Crs.
D9: Years | E9: 2021 | F9: 2022 | G9: 2023 | H9: 2024 | I9: 2025 | K9: 2025
D10: Equity Share Capital | E10: 551.28 | F10: 554.55 | G10: 557.97 | H10: 759.69 | I10: 765.22 | K10: Item | L10: Amount (₹ Crs.)
D11: Reserves | E11: 209258.9 | F11: 246771.62 | G11: 288879.53 | H11: 455635.56 | I11: 521024.17 | K11: Capital | L11: 765.2222
D12: Borrowings | E12: 1511417.6 | F12: 1784969.5 | G12: 2139211.9 | H12: 3107502.7 | I12: 3345503.8 | K12: ESOP Outstanding | L12: 3805.1944
D13: Other Liabilities | E13: 78278.83 | F13: 90638.6 | G13: 101783.03 | H13: 466296.27 | I13: 524816.64 | K13: Reserves & Surplus | L13: 496854.22
D14: Total | E14: 1799506.6 | F14: 2122934.3 | G14: 2530432.4 | H14: 4030194.3 | I14: 4392109.8 | K14: Total Equity | L14: 501424.64
D15: Net Block | E15: 5248.35 | F15: 6432.07 | G15: 8431.35 | H15: 12603.76 | I15: 15257.94 | K15: Borrowings (Debt) | L15: 547930.89
D16: Capital Work in Progress
D17: Investments | E17: 438823.11 | F17: 449263.86 | G17: 511581.71 | H17: 1005681.6 | I17: 1186472.9
D18: Other Assets | E18: 1355435.2 | F18: 1667238.4 | G18: 2010419.4 | H18: 3011908.9 | I18: 3190379 | K18: Tax rate: | L18: 0.2517
D19: Total | E19: 1799506.6 | F19: 2122934.3 | G19: 2530432.4 | H19: 4030194.3 | I19: 4392109.8
C20: Balance Sheet | D20: Receivables
D21: Inventory
D22: Cash & Bank | E22: 86648.17 | F22: 118791.2 | G22: 103917.93 | H22: 165658.59 | I22: 132227.37
D23: No. of Equity Shares | E23: 5512776482 | F23: 5545540976 | G23: 5579742786 | H23: 7596910662 | I23: 7652221674
D24: New Bonus Shares
D25: Face value | E25: 1 | F25: 1 | G25: 1 | H25: 1 | I25: 1
D27: Cash and balances with Reserve Bank of India | E27: 97340.736 | F27: 129995.64 | G27: 117160.77 | H27: 178683.22 | I27: 144355.03
D30: Sales | E30: 128552.4 | F30: 135936.41 | G30: 170754.05 | H30: 283649.02 | I30: 336367.43
D31: Raw Material Cost
D32: Change in Inventory
D33: Power and Fuel
D34: Other Mfr. Exp | E34: 1649.11 | F34: 1772.27 | G34: 2176.5 | H34: 3255.75 | I34: 3943.56
D35: Employee Cost | E35: 13682.35 | F35: 15904.81 | G35: 20031.36 | H35: 31050.07 | I35: 34167.89
D36: Selling and admin | E36: 4780.54 | F36: 5406.79 | G36: 6580 | H36: 87580.05 | I36: 105188.45
D37: Other Expenses | E37: 32344.53 | F37: 33473.09 | G37: 34254.44 | H37: 52309.67 | I37: 43674.55
C38: P/L statement | D38: Other Income | E38: 27332.88 | F38: 31758.99 | G38: 33912.05 | H38: 124345.75 | I38: 134548.5
D39: Depreciation | E39: 1385.01 | F39: 1680.73 | G39: 2345.47 | H39: 3092.08 | I39: 3805.23
D40: Interest | E40: 59247.59 | F40: 58584.33 | G40: 77779.94 | H40: 154138.55 | I40: 183894.2
D41: Profit before tax | E41: 42796.15 | F41: 50873.38 | G41: 61498.39 | H41: 76568.6 | I41: 96242.05
D42: Tax | E42: 10939.38 | F42: 12722.48 | G42: 15349.69 | H42: 11122.1 | I42: 22801.88
D43: Net Profit | E43: 31833.21 | F43: 38052.75 | G43: 45997.11 | H43: 64062.04 | I43: 70792.25
D44: Dividend Amount | E44: 3583.32 | F44: 8595.52 | G44: 10601.43 | H44: 14813.96 | I44: 16834.84
D47: Profit before income tax | E47: 41658.9 | F47: 49015.5 | G47: 58485.3 | H47: 70895.3 | I47: 88478.1
D48: Depreciation on fixed assets | E48: 1302.4 | F48: 1600 | G48: 2242.5 | H48: 2810.1 | I48: 3379.5
D49: (Profit)/loss on revaluation of investments | E49: 1485.3 | F49: -1546.4 | G49: 545.8 | H49: -943.5 | I49: 268.4
D50: Amortisation of premium/(discount) on investments | E50: 765.5 | F50: 821.3 | G50: 851.2 | H50: 844.9 | I50: -27.9
D51: Profit on sale of fixed assets | E51: -0.2 | F51: 3.3 | G51: -8.3 | H51: -73.8 | I51: -22.7
...
