Workbook

Sheet Historical Data
A1: INFOSYS- (Historical Returns past 5 years)
B6: Year | C6: 2019 | D6: 2020 | E6: 2021 | F6: 2022 | G6: 2023 | H6: 2024 | I6: 2025
B7: Revenue | C7: 82675 | D7: 90791 | E7: 100472 | F7: 121641 | G7: 146767 | H7: 153670 | I7: 162990
B8: EBIT | C8: 21041 | D8: 22177 | E8: 26823 | F8: 30310 | G8: 33606 | H8: 36458 | I8: 38024
B9: EBIT Margin | C9: =C8/C7 -> 0.25450257 | D9: =D8/D7 -> 0.2442643 | E9: =E8/E7 -> 0.2669699 | F9: =F8/F7 -> 0.24917585 | G9: =G8/G7 -> 0.22897518 | H9: =H8/H7 -> 0.23724865 | I9: =I8/I7 -> 0.23329039
B10: Net Income | C10: 15404 | D10: 16594 | E10: 19351 | F10: 22110 | G10: 24095 | H10: 26233 | I10: 26713
B11: Depreciation | C11: 2011 | D11: 2893 | E11: 3267 | F11: 3476 | G11: 4225 | H11: 4678 | I11: 4812
B12: Depreciation as % of Revenue | C12: =C11/C7 -> 0.024324161 | D12: =D11/D7 -> 0.031864392 | E12: =E11/E7 -> 0.032516522 | F12: =F11/F7 -> 0.028575891 | G12: =G11/G7 -> 0.028787125 | H12: =H11/H7 -> 0.030441856 | I12: =I11/I7 -> 0.029523284
B13: CapEx | C13: 632 | D13: 331 | E13: 7373 | F13: 6485 | G13: 1071 | H13: 5093 | I13: 1864
B14: CapEx as % of Revenue | C14: =C13/C7 -> 0.0076443907 | D14: =D13/D7 -> 0.0036457358 | E14: =E13/E7 -> 0.073383629 | F14: =F13/F7 -> 0.053312617 | G14: =G13/G7 -> 0.0072972807 | H14: =H13/H7 -> 0.033142448 | I14: =I13/I7 -> 0.011436284
B15: Change in Working Capital | C15: -1991 | D15: -41 | E15: 4496 | F15: -6760 | G15: 431 | H15: 9222 | I15: 4792
B16: Δ in WC as % of Revenue | C16: =C15/C7 -> -0.02408225 | D16: =D15/D7 -> -0.00045158661 | E16: =E15/E7 -> 0.044748786 | F16: =F15/F7 -> -0.055573368 | G16: =G15/G7 -> 0.0029366274 | H16: =H15/H7 -> 0.060011713 | I16: =I15/I7 -> 0.029400577
B17: Cash Flow from Operations (CFO) | C17: 14841 | D17: 17003 | E17: 23224 | F17: 23885 | G17: 22467 | H17: 25210 | I17: 35694
B18: Total Debt | C18: 0 | D18: 4633 | E18: 5325 | F18: 5474 | G18: 8299 | H18: 8359 | I18: 8227
B19: Cash & Cash equivalents | C19: 19568 | D19: 18649 | E19: 24714 | F19: 17472 | G19: 12173 | H19: 14786 | I19: 24455
B20: Shares Outstanding | C20: 414.52083
B23: Average Depreciation as % of Revenue | C23: =AVERAGE(C12:I12) -> 0.029433319
B24: Average CapEx as % of Revenue | C24: =AVERAGE(C14:I14) -> 0.027123198
B25: Average Δ in WC as % of Revenue | C25: =AVERAGE(C16:I16) -> 0.0081414999

Sheet Assumptions
A1: Assumptions
A5: Forecast Horizon | B5: Historical Years Used: | C5: 7 Years
B6: Projection Period: | C6: 5 Years
B7: Valuation Method: | C7: FCFF (Free Cash Flow to Firm)
B8: Currency: | C8: INR (₹ Crores)
A9: Revenue Growth Assumptions | B9: Revenue Growth (Base Case): | C9: 0.06
B10: Bull Case: | C10: 0.08
B11: Bear Case: | C11: 0.04
B13: Rationale: | C13: Infosys has delivered stable mid-single-digit to high-single-digit growth historically with strong visibility from long-term digital transformation deals.
A14: EBIT Margin Assumptions | B14: EBIT Margin (Base Case): | C14: 0.215
B15: Bull Case: | C15: 0.24
B16: Bear Case: | C16: 0.2
B18: Rationale: | C18: Historically stable operating margin driven by offshore model and cost efficiency.
A19: Tax Rate | B19: Effective Tax Rate: | C19: 0.2887
B20: Source: | C20: Historical tax expense trend + India corporate tax regime.
A21: Depreciation, change in WACC & CapEx | B21: CapEx is approximated using the absolute value of “Net Cash Used in Investing Activities” because Infosys is a low asset-intensive business with minimal M&A activity.
B24: Formula Used: | C24: CapEx ≈ [Net Cash Used in Investing Activities]
B25: Rationale: | C25: Infosys' investing cash flows are almost entirely CapEx (PPE + intangibles).
B26: CapEx: | C26: ='Historical Data'!C24 -> 0.027123198
B27: Depreciation: | C27: ='Historical Data'!C23 -> 0.029433319
B28: Δ in WC: | C28: ='Historical Data'!C25 -> 0.0081414999
B29: Rationale: | C29: Based on historical range for Infosys, Average of % of revenue of last 7 years.
A30: WACC (Weighted Average Cost of Capital) | B30: Cost of Equity (Re) - via CAPM
B31: Risk-Free Rate (India 5Y Bond): | C31: 0.062063
B32: Beta (Infosys): | C32: 0.81
B33: Market Rate of Return (Rm): | C33: 0.091475
B34: Equity Risk Premium (Rm-Rf): | C34: =C33-C31 -> 0.029412
B35: CAPM:
B36: Re = Rf + Beta × MRP
B37: Re = | C37: =C31+C34*C32 -> 0.08588672
B38: Cost of Debt (Rd)
B39: Pre-tax Cost of Debt: | C39: 0.045
B40: Tax Rate: | C40: =C19 -> 0.2887
B41: After-tax Cost of Debt
B42: Rd × (1 – Tax Rate)= | C42: =C39*(1-C40) -> 0.0320085
B43: Capital Structure
B44: Current D/E ratio: | C44: 0.06
B45: Equity Weight (E/V): (Ke) | C45: =1/(1+C44) -> 0.94339623
B46: Debt Weight (D/V): (Kd) | C46: =C44/(1+C44) -> 0.056603774
B47: Final WACC
...

Sheet Forecast
A1: 5 Years Forecast
D5: Year | E5: 2026 | F5: 2027 | G5: 2028 | H5: 2029 | I5: 2030
D6: Revenue | E6: ='Historical Data'!$I$7*(1+Forecast!L6) -> 172769.4 | F6: =E6*(1+$L$6) -> 183135.56 | G6: =F6*(1+$L$6) -> 194123.7 | H6: =G6*(1+$L$6) -> 205771.12 | I6: =H6*(1+$L$6) -> 218117.39 | K6: =Assumptions!B9 -> Revenue Growth (Base Case): | L6: =Assumptions!C9 -> 0.06
D7: EBIT | E7: =E6*$L$7 -> 37145.421 | F7: =F6*$L$7 -> 39374.146 | G7: =G6*$L$7 -> 41736.595 | H7: =H6*$L$7 -> 44240.791 | I7: =I6*$L$7 -> 46895.238 | K7: =Assumptions!B14 -> EBIT Margin (Base Case): | L7: =Assumptions!C14 -> 0.215
D8: NOPAT | E8: =E7*(1-$L$8) -> 26421.538 | F8: =F7*(1-$L$8) -> 28006.83 | G8: =G7*(1-$L$8) -> 29687.24 | H8: =H7*(1-$L$8) -> 31468.474 | I8: =I7*(1-$L$8) -> 33356.583 | K8: =Assumptions!B19 -> Effective Tax Rate: | L8: =Assumptions!C19 -> 0.2887
D9: Depreciation | E9: =E6*$L$9 -> 5085.1768 | F9: =F6*$L$9 -> 5390.2874 | G9: =G6*$L$9 -> 5713.7047 | H9: =H6*$L$9 -> 6056.5269 | I9: =I6*$L$9 -> 6419.9186 | K9: =Assumptions!B27 -> Depreciation: | L9: =Assumptions!C27 -> 0.029433319
D10: CapEx | E10: =E6*$L$10 -> 4686.0586 | F10: =F6*$L$10 -> 4967.2222 | G10: =G6*$L$10 -> 5265.2555 | H10: =H6*$L$10 -> 5581.1708 | I10: =I6*$L$10 -> 5916.0411 | K10: =Assumptions!B26 -> CapEx: | L10: =Assumptions!C26 -> 0.027123198
D11: Change in WC | E11: =E6*$L$11 -> 1406.6021 | F11: =F6*$L$11 -> 1490.9982 | G11: =G6*$L$11 -> 1580.4581 | H11: =H6*$L$11 -> 1675.2856 | I11: =I6*$L$11 -> 1775.8027 | K11: =Assumptions!B28 -> Δ in WC: | L11: =Assumptions!C28 -> 0.0081414999
D12: FCFF | E12: =E8+E9-E10-E11 -> 25414.054 | F12: =F8+F9-F10-F11 -> 26938.897 | G12: =G8+G9-G10-G11 -> 28555.231 | H12: =H8+H9-H10-H11 -> 30268.545 | I12: =I8+I9-I10-I11 -> 32084.658

Sheet WACC
A1: WACC
A4: Cost of Equity (Re) - via CAPM
B5: =Assumptions!B31 -> Risk-Free Rate (India 5Y Bond): | E5: =Assumptions!C31 -> 0.062063
B6: =Assumptions!B32 -> Beta (Infosys): | E6: =Assumptions!C32 -> 0.81
B7: =Assumptions!B33 -> Market Rate of Return (Rm): | E7: =Assumptions!C33 -> 0.091475
B8: =Assumptions!B34 -> Equity Risk Premium (Rm-Rf): | E8: =E7-E5 -> 0.029412
B10: =Assumptions!B35 -> CAPM: | E10: =Assumptions!B36 -> Re = Rf + Beta × MRP
D11: =Assumptions!B37 -> Re = | E11: =E5+E8*E6 -> 0.08588672
A13: =Assumptions!B38 -> Cost of Debt (Rd)
B14: =Assumptions!B39 -> Pre-tax Cost of Debt: | E14: =Assumptions!C39 -> 0.045
B15: =Assumptions!B40 -> Tax Rate: | E15: =Assumptions!C40 -> 0.2887
B16: =Assumptions!B41 -> After-tax Cost of Debt | E16: =Assumptions!B42 -> Rd × (1 – Tax Rate)= | G16: =E14*(1-E15) -> 0.0320085
A18: =Assumptions!B43 -> Capital Structure
B19: =Assumptions!B44 -> Current D/E ratio: | E19: =Assumptions!C44 -> 0.06
B20: =Assumptions!B45 -> Equity Weight (E/V): (Ke) | E20: =1/(1+E19) -> 0.94339623
B21: =Assumptions!B46 -> Debt Weight (D/V): (Kd) | E21: =1-E20 -> 0.056603774
A23: =Assumptions!B47 -> Final WACC
B24: =Assumptions!B48 -> WACC = | E24: =Assumptions!C48 -> Re*Ke + Rd*Kd*(1-tax)
D26: =Assumptions!B49 -> WACC = | E26: =E11*E20+G16*E21 -> 0.082837009

Sheet Valuation
A1: Valuation
C4: 1 | D4: 2 | E4: 3 | F4: 4 | G4: 5
B5: YEARS | C5: =Forecast!E5 -> 2026 | D5: =Forecast!F5 -> 2027 | E5: =Forecast!G5 -> 2028 | F5: =Forecast!H5 -> 2029 | G5: =Forecast!I5 -> 2030 | H5: Terminal
B6: FCFF | C6: =Forecast!E12 -> 25414.054 | D6: =Forecast!F12 -> 26938.897 | E6: =Forecast!G12 -> 28555.231 | F6: =Forecast!H12 -> 30268.545 | G6: =Forecast!I12 -> 32084.658 | H6: -
B7: Discount Factor | C7: =1/(1+$C$18)^C4 -> 0.92350002 | D7: =1/(1+$C$18)^D4 -> 0.85285229 | E7: =1/(1+$C$18)^E4 -> 0.7876091 | F7: =1/(1+$C$18)^F4 -> 0.72735702 | G7: =1/(1+$C$18)^G4 -> 0.67171423 | H7: -
B8: PV of FCFF | C8: =C6*C7 -> 23469.879 | D8: =D6*D7 -> 22974.9 | E8: =E6*E7 -> 22490.36 | F8: =F6*F7 -> 22016.039 | G8: =G6*G7 -> 21551.721 | H8: -
B9: Terminal Value | C9: - | D9: - | E9: - | F9: - | G9: - | H9: =G6*(1+C19)/(C18-C19) -> 778953.63
B10: PV of TV | C10: - | D10: - | E10: - | F10: - | G10: - | H10: =H9*G7 -> 523234.24
B11: Enterprise Value (EV) | C11: =SUM(C8:G8)+H10 -> 635737.13
B12: Cash | C12: =Assumptions!C53 -> 24455
B13: Debt | C13: =Assumptions!C54 -> 8227
B14: Equity Value | C14: EV + Cash – Debt | E14: =C11+C12-C13 -> 651965.13
B15: Intrinsic Value/share | C15: Equity value / (Shares o/s) | E15: =E14/C20 -> 1572.8164
B18: =WACC!D26 -> WACC = | C18: =WACC!E26 -> 0.082837009
B19: Terminal Growth (g) | C19: =Assumptions!C51 -> 0.04
B20: Shares o/s | C20: =Assumptions!B56 -> 414.52083

Sheet Sensitivity Analysis
A1: Sensitivity Analysis
E5: WACC
G6: (Base)
D7: =Valuation!E15 -> 1572.8164 | E7: =F7-1% -> 0.0628 | F7: =G7-1% -> 0.0728 | G7: 0.0828 | H7: =G7+1% -> 0.0928 | I7: =H7+1% -> 0.1028
B8: Growth Rate | D8: =D9-0.5% -> 0.03 | E8: 2118.56 | F8: 1629 | G8: 1324.99 | H8: 1117.89 | I8: 967.75
D9: =D10-0.5% -> 0.035 | E9: 2451.21 | F9: 1809.6 | G9: 1436.54 | H9: 1192.65 | I9: 1020.76
C10: (Base) | D10: 0.04 | E10: 2929.77 | F10: 2045.25 | G10: 1574.15 | H10: 1281.57 | I10: 1082.22
D11: =D10+0.5% -> 0.045 | E11: 3677.18 | F11: 2365.68 | G11: 1748.17 | H11: 1389.09 | I11: 1154.3
D12: =D11+0.5% -> 0.05 | E12: 5008.51 | F12: 2826.64 | G12: 1975.24 | H12: 1521.73 | I12: 1240.04
