Workbook
Name Slicer_Metric: #N/A
Name Slicer_Year__Year: #N/A

Sheet Dashboard
C1: =_xlfn.XLOOKUP('Profit and loss'!A14,'Profit and loss'!A4:A17,'Profit and loss'!D4:D17) -> 1869.28 | D1: =_xlfn.XLOOKUP('Profit and loss'!A5,'Profit and loss'!A4:A17,'Profit and loss'!D4:D17) -> 28152.5 | E1: =_xlfn.XLOOKUP(Analysis!A18,Analysis!A14:A21,Analysis!D14:D21) -> 0.10110523 | F1: =_xlfn.XLOOKUP(Analysis!B29,Analysis!B25:B32,Analysis!E25:E32) -> 0.1349421 | Q1: =_xlfn.XLOOKUP(P2,Analysis!E6:E10,Analysis!F6:F10) -> 0.069573473
A2: DASHBOARD | N2: CAGR: | P2: Revenue
A28: =IF(OR(J28="All",J28="2025"),'Cash Flow'!D4,IF(J28="2024",'Cash Flow'!C4,'Cash Flow'!B4)) -> 45747 | I28: Year: | J28: {=CUBERANKEDMEMBER("ThisWorkbookDataModel",Slicer_Year__Year,1)} -> 2025

Sheet DATA SHEET
A1: COMPANY NAME | B1: MRF LTD
A2: Number of shares | B2: =IF(B5>0, B5/B4, 0) -> 0.4241143 | C2: (in Crs) | G2: All the values are in Crs
A3: Face Value | B3: 10
A4: Current Price | B4: 147505
A5: Market Capitalization | B5: 62558.98 | C5: (in Crs)
A7: PROFIT & LOSS
A8: Report Date | B8: 45016 | C8: 45382 | D8: 45747
A9: Sales | B9: 23008.33 | C9: 25168.73 | D9: 28152.5
A10: Raw Material Cost | B10: 15786.49 | C10: 15265.35 | D10: 18516.43
A11: Gross Profit | B11: =B9-B10 -> 7221.84 | C11: =C9-C10 -> 9903.38 | D11: =D9-D10 -> 9636.07
A12: Change in Inventory | B12: 346.91 | C12: 184.32 | D12: 590.31
A13: Power and Fuel | B13: 1136.03 | C13: 1148.65 | D13: 1215.59
A14: Other Mfr. Exp | B14: 958.08 | C14: 1066.43 | D14: 1212.72
A15: Employee Cost | B15: 1595.65 | C15: 1798.47 | D15: 1885.45
A16: Selling and admin | B16: 1241.15 | C16: 1551.58 | D16: 1580
A17: Other Expenses | B17: 233.65 | C17: 250.31 | D17: 237.97
A18: Other Income | B18: 245.02 | C18: 306.16 | D18: 405.67
A19: Depreciation | B19: 1253.04 | C19: 1429.97 | D19: 1653.55
A20: Interest | B20: 326.45 | C20: 361.03 | D20: 367.77
A21: Profit before tax | B21: 1069.72 | C21: 2787.42 | D21: 2479
A22: Tax | B22: 300.78 | C22: 706.19 | D22: 609.71
A23: Net profit | B23: 768.93 | C23: 2081.22 | D23: 1869.28
A24: Dividend Amount | B24: 74.2 | C24: 84.8 | D24: 99.64
A27: BALANCE SHEET
A28: Report Date | B28: 45016 | C28: 45382 | D28: 45747
A29: Equity Share Capital | B29: 4.24 | C29: 4.24 | D29: 4.24
A30: Reserves | B30: 14703.42 | C30: 16698.75 | D30: 18484.22
A31: Borrowings | B31: 3013.61 | C31: 2821.5 | D31: 3771.16
A32: Other Liabilities | B32: 6648.14 | C32: 7324.94 | D32: 7307.37
A33: Total | B33: 24369.41 | C33: 26849.43 | D33: 29566.99
A34: Net Block | B34: 10117.97 | C34: 12046.22 | D34: 13220.78
A35: Capital Work in Progress | B35: 3045.86 | C35: 2384.53 | D35: 1168.63
A36: Investments | B36: 3085.11 | C36: 3382.97 | D36: 4548.24
A37: Other Assets | B37: 8120.47 | C37: 9035.71 | D37: 10629.34
A38: Total | B38: 24369.41 | C38: 26849.43 | D38: 29566.99
A39: Receivables | B39: 2503.27 | C39: 2911.96 | D39: 3370.25
... A42: No. of Equity Shares | B42: 4241143 | C42: 4241143 | D42: 4241143
A43: New Bonus Shares
A44: Face value | B44: 10 | C44: 10 | D44: 10
A47: CASH FLOW:
...

Sheet Profit and loss
A1: ='DATA SHEET'!B1 -> MRF LTD | B1: Profit & Loss Statement
A2: No. of Years
A3: =COUNT(A4:E4) -> 3
A4: Narration | B4: ='DATA SHEET'!B8 -> 45016 | C4: ='DATA SHEET'!C8 -> 45382 | D4: ='DATA SHEET'!D8 -> 45747 | F4: CAGR
A5: =PROPER("Sales") -> Sales | B5: ='DATA SHEET'!B9 -> 23008.33 | C5: ='DATA SHEET'!C9 -> 25168.73 | D5: ='DATA SHEET'!D9 -> 28152.5 | F5: =IF(B5>0,(D5/B5)^(1/$A$3)-1,"") -> 0.069573473
A6: Expenses | B6: =SUM('DATA SHEET'!B10,'DATA SHEET'!B13:B17,-1*'DATA SHEET'!B12) -> 20604.14 | C6: =SUM('DATA SHEET'!C10,'DATA SHEET'!C13:C17,-1*'DATA SHEET'!C12) -> 20896.47 | D6: =SUM('DATA SHEET'!D10,'DATA SHEET'!D13:D17,-1*'DATA SHEET'!D12) -> 24057.85 | F6: =IF(B6>0,(D6/B6)^(1/$A$3)-1,"") -> 0.053013907
A7: Operating Profit | B7: =B5-B6 -> 2404.19 | C7: =C5-C6 -> 4272.26 | D7: =D5-D6 -> 4094.65 | F7: =IF(B7>0,(D7/B7)^(1/$A$3)-1,"") -> 0.1942154
A8: Other Income | B8: ='DATA SHEET'!B18 -> 245.02 | C8: ='DATA SHEET'!C18 -> 306.16 | D8: ='DATA SHEET'!D18 -> 405.67 | F8: =IF(B8>0,(D8/B8)^(1/$A$3)-1,"") -> 0.18301555
A9: EBITDA | B9: =SUM(B7:B8) -> 2649.21 | C9: =SUM(C7:C8) -> 4578.42 | D9: =SUM(D7:D8) -> 4500.32 | F9: =IF(B9>0,(D9/B9)^(1/$A$3)-1,"") -> 0.19318835
A10: Depreciation | B10: ='DATA SHEET'!B19 -> 1253.04 | C10: ='DATA SHEET'!C19 -> 1429.97 | D10: ='DATA SHEET'!D19 -> 1653.55 | F10: =IF(B10>0,(D10/B10)^(1/$A$3)-1,"") -> 0.096858989
A11: Interest | B11: ='DATA SHEET'!B20 -> 326.45 | C11: ='DATA SHEET'!C20 -> 361.03 | D11: ='DATA SHEET'!D20 -> 367.77 | F11: =IF(B11>0,(D11/B11)^(1/$A$3)-1,"") -> 0.040526653
A12: Profit before tax | B12: ='DATA SHEET'!B21 -> 1069.72 | C12: ='DATA SHEET'!C21 -> 2787.42 | D12: ='DATA SHEET'!D21 -> 2479 | F12: =IF(B12>0,(D12/B12)^(1/$A$3)-1,"") -> 0.32333197
A13: Tax | B13: ='DATA SHEET'!B22 -> 300.78 | C13: ='DATA SHEET'!C22 -> 706.19 | D13: ='DATA SHEET'!D22 -> 609.71 | F13: =IF(B13>0,(D13/B13)^(1/$A$3)-1,"") -> 0.26558539
A14: Net profit | B14: ='DATA SHEET'!B23 -> 768.93 | C14: ='DATA SHEET'!C23 -> 2081.22 | D14: ='DATA SHEET'!D23 -> 1869.28 | F14: =IF(B14>0,(D14/B14)^(1/$A$3)-1,"") -> 0.3446085
A15: EPS | B15: =IF('DATA SHEET'!B58>0,'Profit and loss'!B14/'DATA SHEET'!B58," ") -> 1830.7857 | C15: =IF('DATA SHEET'!C58>0,'Profit and loss'!C14/'DATA SHEET'!C58," ") -> 4955.2857 | D15: =IF('DATA SHEET'!D58>0,'Profit and loss'!D14/'DATA SHEET'!D58," ") -> 4450.6667 | F15: =IF(B15>0,(D15/B15)^(1/$A$3)-1,"") -> 0.3446085
A16: Price to earning | B16: =IF(B15>0,B17/B15," ") -> 45.907721 | C16: =IF(C15>0,C17/C15," ") -> 26.918185 | D16: =IF(D15>0,D17/D15," ") -> 25.31705 | F16: =IF(B16>0,(D16/B16)^(1/$A$3)-1,"") -> -0.17994599
A17: Share Price | B17: ='DATA SHEET'!B55 -> 84047.2 | C17: ='DATA SHEET'!C55 -> 133387.3 | D17: ='DATA SHEET'!D55 -> 112677.75 | F17: =IF(B17>0,(D17/B17)^(1/$A$3)-1,"") -> 0.10265158
F18: =IF(B18>0,(D18/B18)^(1/$A$3)-1,"")
F19: =IF(B19>0,(D19/B19)^(1/$A$3)-1,"")
A20: Market Cap | B20: =B17*'DATA SHEET'!B58 -> 35299.824 | C20: =C17*'DATA SHEET'!C58 -> 56022.666 | D20: =D17*'DATA SHEET'!D58 -> 47324.655 | F20: =IF(B20>0,(D20/B20)^(1/$A$3)-1,"") -> 0.10265158
A21: (Total Equity)
A23: RATIOS:
A24: Dividend Payout | B24: =IF('DATA SHEET'!B23>0,'DATA SHEET'!B24/'DATA SHEET'!B23," ") -> 0.096497731 | C24: =IF('DATA SHEET'!C23>0,'DATA SHEET'!C24/'DATA SHEET'!C23," ") -> 0.040745332 | D24: =IF('DATA SHEET'!D23>0,'DATA SHEET'!D24/'DATA SHEET'!D23," ") -> 0.053303946
A25: OPM | B25: =IF(B7>0,B7/B5," ") -> 0.10449216 | C25: =IF(C7>0,C7/C5," ") -> 0.16974476 | D25: =IF(D7>0,D7/D5," ") -> 0.14544534
A26: (Operating Profit Margin)
A29: Sales | B29: ='DATA SHEET'!B9 -> 23008.33 | C29: ='DATA SHEET'!C9 -> 25168.73 | D29: ='DATA SHEET'!D9 -> 28152.5
A30: Raw Material Cost | B30: ='DATA SHEET'!B10 -> 15786.49 | C30: ='DATA SHEET'!C10 -> 15265.35 | D30: ='DATA SHEET'!D10 -> 18516.43
A31: Gross Profit | B31: =B29-B30 -> 7221.84 | C31: =C29-C30 -> 9903.38 | D31: =D29-D30 -> 9636.07
B34: 3 YEARS
A35: Sales Growth
A36: OPM | B36: =IF(SUM(B5:D5)=0,"",SUMPRODUCT(B25:D25,B5:D5)/SUM(B5:D5)) -> 0.14111309
A37: Price to Earning | B37: =AVERAGEIF(B16:D16,">0") -> 32.714319

Sheet Balance Sheet
A1: ='Profit and loss'!A1 -> MRF LTD | B1: Balance Sheet
A4: Narration | B4: ='DATA SHEET'!B8 -> 45016 | C4: ='DATA SHEET'!C8 -> 45382 | D4: ='DATA SHEET'!D8 -> 45747 | F4: CAGR
A5: Equity Share Capital | B5: ='DATA SHEET'!B29 -> 4.24 | C5: ='DATA SHEET'!C29 -> 4.24 | D5: ='DATA SHEET'!D29 -> 4.24 | F5: =IF(B5>0,(D5/B5)^(1/'Profit and loss'!$A$3)-1,"") -> 0
A6: Reserves | B6: ='DATA SHEET'!B30 -> 14703.42 | C6: ='DATA SHEET'!C30 -> 16698.75 | D6: ='DATA SHEET'!D30 -> 18484.22 | F6: =IF(B6>0,(D6/B6)^(1/'Profit and loss'!$A$3)-1,"") -> 0.079263746
A7: Borrowings | B7: ='DATA SHEET'!B31 -> 3013.61 | C7: ='DATA SHEET'!C31 -> 2821.5 | D7: ='DATA SHEET'!D31 -> 3771.16 | F7: =IF(B7>0,(D7/B7)^(1/'Profit and loss'!$A$3)-1,"") -> 0.077612541
A8: Other Liabilities | B8: ='DATA SHEET'!B32 -> 6648.14 | C8: ='DATA SHEET'!C32 -> 7324.94 | D8: ='DATA SHEET'!D32 -> 7307.37 | F8: =IF(B8>0,(D8/B8)^(1/'Profit and loss'!$A$3)-1,"") -> 0.032017307
A9: Total | B9: ='DATA SHEET'!B33 -> 24369.41 | C9: ='DATA SHEET'!C33 -> 26849.43 | D9: ='DATA SHEET'!D33 -> 29566.99 | F9: =IF(B9>0,(D9/B9)^(1/'Profit and loss'!$A$3)-1,"") -> 0.066565095
F10: =IF(B10>0,(D10/B10)^(1/'Profit and loss'!$A$3)-1,"")
A11: Net Block | B11: ='DATA SHEET'!B34 -> 10117.97 | C11: ='DATA SHEET'!C34 -> 12046.22 | D11: ='DATA SHEET'!D34 -> 13220.78 | F11: =IF(B11>0,(D11/B11)^(1/'Profit and loss'!$A$3)-1,"") -> 0.093254391
A12: Capital Work in Progress | B12: ='DATA SHEET'!B35 -> 3045.86 | C12: ='DATA SHEET'!C35 -> 2384.53 | D12: ='DATA SHEET'!D35 -> 1168.63 | F12: =IF(B12>0,(D12/B12)^(1/'Profit and loss'!$A$3)-1,"") -> -0.27335487
A13: Investments | B13: ='DATA SHEET'!B36 -> 3085.11 | C13: ='DATA SHEET'!C36 -> 3382.97 | D13: ='DATA SHEET'!D36 -> 4548.24 | F13: =IF(B13>0,(D13/B13)^(1/'Profit and loss'!$A$3)-1,"") -> 0.13812747
A14: Other Assets | B14: ='DATA SHEET'!B37 -> 8120.47 | C14: ='DATA SHEET'!C37 -> 9035.71 | D14: ='DATA SHEET'!D37 -> 10629.34 | F14: =IF(B14>0,(D14/B14)^(1/'Profit and loss'!$A$3)-1,"") -> 0.093893506
A15: Total | B15: ='DATA SHEET'!B38 -> 24369.41 | C15: ='DATA SHEET'!C38 -> 26849.43 | D15: ='DATA SHEET'!D38 -> 29566.99 | F15: =IF(B15>0,(D15/B15)^(1/'Profit and loss'!$A$3)-1,"") -> 0.066565095
F16: =IF(B16>0,(D16/B16)^(1/'Profit and loss'!$A$3)-1,"")
A17: Working Capital | B17: =B14-B8 -> 1472.33 | C17: =C14-C8 -> 1710.77 | D17: =D14-D8 -> 3321.97 | F17: =IF(B17>0,(D17/B17)^(1/'Profit and loss'!$A$3)-1,"") -> 0.31158623
A18: Debtors | B18: ='DATA SHEET'!B39 -> 2503.27 | C18: ='DATA SHEET'!C39 -> 2911.96 | D18: ='DATA SHEET'!D39 -> 3370.25 | F18: =IF(B18>0,(D18/B18)^(1/'Profit and loss'!$A$3)-1,"") -> 0.10420949
A19: Inventory | B19: ='DATA SHEET'!B40 -> 4141.05 | C19: ='DATA SHEET'!C40 -> 4468.58 | D19: ='DATA SHEET'!D40 -> 5624.78 | F19: =IF(B19>0,(D19/B19)^(1/'Profit and loss'!$A$3)-1,"") -> 0.10746928
A21: Debtor Days | B21: =IF('Profit and loss'!B5>0,'Balance Sheet'!B18/('Profit and loss'!B5/365),0) -> 39.711424 | C21: =IF('Profit and loss'!C5>0,'Balance Sheet'!C18/('Profit and loss'!C5/365),0) -> 42.2296 | D21: =IF('Profit and loss'!D5>0,'Balance Sheet'!D18/('Profit and loss'!D5/365),0) -> 43.695631
A22: Inventory Turnover | B22: =IF(B19>0,'Profit and loss'!B5/'Balance Sheet'!B19,0) -> 5.5561585 | C22: =IF(C19>0,'Profit and loss'!C5/'Balance Sheet'!C19,0) -> 5.6323776 | D22: =IF(D19>0,'Profit and loss'!D5/'Balance Sheet'!D19,0) -> 5.0050846
A24: Return on Equity | B24: =IF(SUM(B5:B6)>0,'Profit and loss'!B14/SUM('Balance Sheet'!B5:B6)) -> 0.05228092 | C24: =IF(SUM(C5:C6)>0,'Profit and loss'!C14/SUM('Balance Sheet'!C5:C6)) -> 0.12460164 | D24: =IF(SUM(D5:D6)>0,'Profit and loss'!D14/SUM('Balance Sheet'!D5:D6)) -> 0.10110523
A25: Return on Capital Employed | B25: =IF(B15-SUM(B5:B7)>0,SUM('Profit and loss'!B11:B12)/(B15-SUM(B5:B7))) -> 0.21000912 | C25: =IF(C15-SUM(C5:C7)>0,SUM('Profit and loss'!C11:C12)/(C15-SUM(C5:C7))) -> 0.42982605 | D25: =IF(D15-SUM(D5:D7)>0,SUM('Profit and loss'!D11:D12)/(D15-SUM(D5:D7))) -> 0.38957518
A26: EBIT/(Total Assets-Current Liabilities)
A27: Return on Assets | B27: =IF(B15>0,'Profit and loss'!B14/'Balance Sheet'!B15,"") -> 0.031553082 | C27: =IF(AVERAGE(B15,C15)>0,'Profit and loss'!C14/AVERAGE(B15,C15)) -> 0.081267752 | D27: =IF(AVERAGE(C15,D15)>0,'Profit and loss'!D14/AVERAGE(C15,D15)) -> 0.066267232

Sheet Cash Flow
A1: ='Balance Sheet'!A1 -> MRF LTD | B1: Cashflow Statement
A4: Narration | B4: ='DATA SHEET'!B48 -> 45016 | C4: ='DATA SHEET'!C48 -> 45382 | D4: ='DATA SHEET'!D48 -> 45747
A5: =PROPER('DATA SHEET'!A49) -> Cash From Operating Activity | B5: ='DATA SHEET'!B49 -> 2755.47 | C5: ='DATA SHEET'!C49 -> 3303.36 | D5: ='DATA SHEET'!D49 -> 1867.8
A6: =PROPER('DATA SHEET'!A50) -> Cash From Investing Activity | B6: ='DATA SHEET'!B50 -> -1921.81 | C6: ='DATA SHEET'!C50 -> -2380.58 | D6: ='DATA SHEET'!D50 -> -2082.23
A7: =PROPER('DATA SHEET'!A51) -> Cash From Financing Activity | B7: ='DATA SHEET'!B51 -> -839.54 | C7: ='DATA SHEET'!C51 -> -868.22 | D7: ='DATA SHEET'!D51 -> 282
A8: =PROPER('DATA SHEET'!A52) -> Net Cash Flow | B8: ='DATA SHEET'!B52 -> -5.88 | C8: ='DATA SHEET'!C52 -> 54.56 | D8: ='DATA SHEET'!D52 -> 67.57
B27: Helper Table
B28: {=TRANSPOSE(Analysis!F14:J15)} -> Year | C28: 45747
B29: CFO | C29: 1867.8
B30: CFI | C30: -2082.23
B31: CFF | C31: 282
B32: Net CF | C32: 67.57
B35: Sum of Value | C35: Column Labels
B36: Row Labels | C36: Net profit | D36: Revenue | E36: Grand Total
B37: 2025 | C37: 1869.28 | D37: 28152.5 | E37: 30021.78
B38: Grand Total | C38: 1869.28 | D38: 28152.5 | E38: 30021.78
B42: Sum of Value | C42: Column Labels
B43: Years | C43: Net Profit Margin | D43: ROE | E43: Grand Total
B44: 2025 | C44: 0.066398366 | D44: 0.10110523 | E44: 0.1675036
B45: Grand Total | C45: 0.066398366 | D45: 0.10110523 | E45: 0.1675036
B49: Sum of Value | C49: Column Labels
B50: Row Labels | C50: CFF | D50: CFI | E50: CFO | F50: Net Cash Flow | G50: Grand Total
B51: 2025 | C51: -2082.23 | D51: 282 | E51: 1867.8 | F51: 67.57 | G51: 135.14
B52: Grand Total | C52: -2082.23 | D52: 282 | E52: 1867.8 | F52: 67.57 | G52: 135.14
B57: Sum of Value | C57: Column Labels
B58: Ratios | C58: 2025 | D58: Grand Total
B59: Cash Ratio | C59: 0.027662491 | D59: 0.027662491
B60: Current Ratio | C60: 1.4778613 | D60: 1.4778613
B61: Gross Profit Margin | C61: 0.34228115 | D61: 0.34228115
B62: Quick Ratio | C62: 0.81079451 | D62: 0.81079451
B63: Grand Total | C63: 2.6585994 | D63: 2.6585994
B65: Sum of Value | C65: Column Labels
B66: Row Labels | C66: Gross Profit Margin | D66: Net Profit Margin | E66: Operating Profit Margin | F66: Grand Total
B67: 2025 | C67: 0.34228115 | D67: 0.066398366 | E67: 0.14544534 | F67: 0.55412486
B68: Grand Total | C68: 0.34228115 | D68: 0.066398366 | E68: 0.14544534 | F68: 0.55412486

Sheet Analysis
A1: Analysis
A5: GROWTH ANALYSIS | E5: CAGR
A6: YoY Growth | B6: 2022-23 to 2023-24 | C6: 2023-24 to 2024-25 | E6: Revenue | F6: ='Profit and loss'!F5 -> 0.069573473
A7: Revenue | B7: =IF('Profit and loss'!B5>0,('Profit and loss'!C5-'Profit and loss'!B5)/'Profit and loss'!B5,"") -> 0.093896428 | C7: =IF('Profit and loss'!C5>0,('Profit and loss'!D5-'Profit and loss'!C5)/'Profit and loss'!C5,"") -> 0.11855068 | E7: EBITDA | F7: ='Profit and loss'!F9 -> 0.19318835
A8: Net Profit | B8: =IF('Profit and loss'!B14>0,('Profit and loss'!C14-'Profit and loss'!B14)/'Profit and loss'!B14,"") -> 1.7066443 | C8: =IF('Profit and loss'!C14>0,('Profit and loss'!D14-'Profit and loss'!C14)/'Profit and loss'!C14,"") -> -0.1018345 | E8: Share Price | F8: ='Profit and loss'!F17 -> 0.10265158
A9: Assets | B9: =IF('Balance Sheet'!B15>0,('Balance Sheet'!C15-'Balance Sheet'!B15)/'Balance Sheet'!B15,"") -> 0.10176775 | C9: =IF('Balance Sheet'!C15>0,('Balance Sheet'!D15-'Balance Sheet'!C15)/'Balance Sheet'!C15,"") -> 0.10121481 | E9: PAT | F9: ='Profit and loss'!F14 -> 0.3446085
A10: Equity | B10: =IF('Profit and loss'!B20>0,('Profit and loss'!C20-'Profit and loss'!B20)/'Profit and loss'!B20,"") -> 0.58705228 | C10: =IF('Profit and loss'!C20>0,('Profit and loss'!D20-'Profit and loss'!C20)/'Profit and loss'!C20,"") -> -0.15525878 | E10: Total Equity | F10: ='Profit and loss'!F20 -> 0.10265158
A13: PROFITABILITY ANALYSIS
A14: Year | B14: =A47 -> 45016 | C14: =A62 -> 45382 | D14: ='Balance Sheet'!D4 -> 45747 | F14: Year | G14: CFO | H14: CFI | I14: CFF | J14: Net CF
A15: Gross Profit Margin | B15: =IF('DATA SHEET'!B9>0,'DATA SHEET'!B11/'DATA SHEET'!B9) -> 0.31387936 | C15: =IF('DATA SHEET'!C9>0,'DATA SHEET'!C11/'DATA SHEET'!C9) -> 0.39347953 | D15: =IF('DATA SHEET'!D9>0,'DATA SHEET'!D11/'DATA SHEET'!D9) -> 0.34228115 | F15: =Dashboard!A28 -> 45747 | G15: =_xlfn.XLOOKUP(F15,'Cash Flow'!B4:D4,'Cash Flow'!B5:D5) -> 1867.8 | H15: =_xlfn.XLOOKUP($F$15,'Cash Flow'!$B$4:$D$4,'Cash Flow'!B6:D6) -> -2082.23 | I15: =_xlfn.XLOOKUP($F$15,'Cash Flow'!$B$4:$D$4,'Cash Flow'!B7:D7) -> 282 | J15: =_xlfn.XLOOKUP($F$15,'Cash Flow'!$B$4:$D$4,'Cash Flow'!B8:D8) -> 67.57
A16: Operating Profit Margin | B16: ='Profit and loss'!B25 -> 0.10449216 | C16: ='Profit and loss'!C25 -> 0.16974476 | D16: ='Profit and loss'!D25 -> 0.14544534
A17: Net Profit Margin | B17: =IF('Profit and loss'!B5>0,'Profit and loss'!B14/'Profit and loss'!B5,"") -> 0.033419635 | C17: =IF('Profit and loss'!C5>0,'Profit and loss'!C14/'Profit and loss'!C5,"") -> 0.082690704 | D17: =IF('Profit and loss'!D5>0,'Profit and loss'!D14/'Profit and loss'!D5,"") -> 0.066398366
A18: ROE | B18: ='Balance Sheet'!B24 -> 0.05228092 | C18: ='Balance Sheet'!C24 -> 0.12460164 | D18: ='Balance Sheet'!D24 -> 0.10110523
A19: ROA | B19: ='Balance Sheet'!B27 -> 0.031553082 | C19: ='Balance Sheet'!C27 -> 0.081267752 | D19: ='Balance Sheet'!D27 -> 0.066267232
A20: EV/EBITDA | B20: =IF('Profit and loss'!B9>0,(SUM('Balance Sheet Detailed'!B29:B30,'Balance Sheet Detailed'!B35:B36)+('DATA SHEET'!B55*'DATA SHEET'!$B$2)-'Balance Sheet Detailed'!B16)/'Profit and loss'!B9,"") -> 14.366736 | C20: =IF('Profit and loss'!C9>0,(SUM('Balance Sheet Detailed'!C29:C30,'Balance Sheet Detailed'!C35:C36)+('DATA SHEET'!C55*'DATA SHEET'!$B$2)-'Balance Sheet Detailed'!C16)/'Profit and loss'!C9,"") -> 12.823857 | D20: =IF('Profit and loss'!D9>0,(SUM('Balance Sheet Detailed'!D29:D30,'Balance Sheet Detailed'!D35:D36)+('DATA SHEET'!D55*'DATA SHEET'!$B$2)-'Balance Sheet Detailed'!D16)/'Profit and loss'!D9,"") -> 11.109727
A21: P/E Ratio | B21: ='Profit and loss'!B16 -> 45.907721 | C21: ='Profit and loss'!C16 -> 26.918185 | D21: ='Profit and loss'!D16 -> 25.31705
A23: Liquidity & Solvency Ratios
C24: ='Balance Sheet'!B4 -> 45016 | D24: ='Balance Sheet'!C4 -> 45382 | E24: ='Balance Sheet'!D4 -> 45747 | F24: CAGR
A25: Liquidity | B25: Current Ratio | C25: =IF(SUM('Balance Sheet Detailed'!B35:B42)>0,SUM('Balance Sheet Detailed'!B13:B20)/SUM('Balance Sheet Detailed'!B35:B42),"") -> 1.218665 | D25: =IF(SUM('Balance Sheet Detailed'!C35:C42)>0,SUM('Balance Sheet Detailed'!C13:C20)/SUM('Balance Sheet Detailed'!C35:C42),"") -> 1.3528484 | E25: =IF(SUM('Balance Sheet Detailed'!D35:D42)>0,SUM('Balance Sheet Detailed'!D13:D20)/SUM('Balance Sheet Detailed'!D35:D42),"") -> 1.4778613 | F25: =((E25/C25)^(1/3))-1 -> 0.066390936
B26: Quick Ratio | C26: =IF(SUM('Balance Sheet Detailed'!B35:B42)>0,SUM('Balance Sheet Detailed'!B14:B16,'Balance Sheet Detailed'!B19)/SUM('Balance Sheet Detailed'!B35:B42),"") -> 0.63454402 | D26: =IF(SUM('Balance Sheet Detailed'!C35:C42)>0,SUM('Balance Sheet Detailed'!C14:C16,'Balance Sheet Detailed'!C19)/SUM('Balance Sheet Detailed'!C35:C42),"") -> 0.73291871 | E26: =IF(SUM('Balance Sheet Detailed'!D35:D42)>0,SUM('Balance Sheet Detailed'!D14:D16,'Balance Sheet Detailed'!D19)/SUM('Balance Sheet Detailed'!D35:D42),"") -> 0.81079451 | F26: =((E26/C26)^(1/3))-1 -> 0.085133111
B27: Cash Ratio | C27: =IF(SUM('Balance Sheet Detailed'!B35:B42)>0,SUM('Balance Sheet Detailed'!B16)/SUM('Balance Sheet Detailed'!B35:B42),"") -> 0.019902873 | D27: =IF(SUM('Balance Sheet Detailed'!C35:C42)>0,SUM('Balance Sheet Detailed'!C16)/SUM('Balance Sheet Detailed'!C35:C42),"") -> 0.03123591 | E27: =IF(SUM('Balance Sheet Detailed'!D35:D42)>0,SUM('Balance Sheet Detailed'!D16)/SUM('Balance Sheet Detailed'!D35:D42),"") -> 0.027662491 | F27: =((E27/C27)^(1/3))-1 -> 0.11598537
A28: Solvency | B28: Debt to total assets | C28: =SUM('Balance Sheet Detailed'!B35:B36,'Balance Sheet Detailed'!B29:B30)/'Balance Sheet Detailed'!B21 -> 0.10661075 | D28: =SUM('Balance Sheet Detailed'!C35:C36,'Balance Sheet Detailed'!C29:C30)/'Balance Sheet Detailed'!C21 -> 0.089990873 | E28: =SUM('Balance Sheet Detailed'!D35:D36,'Balance Sheet Detailed'!D29:D30)/'Balance Sheet Detailed'!D21 -> 0.084296177 | F28: =((E28/C28)^(1/3))-1 -> -0.075296942
B29: Debt to Equity | C29: =SUM('Balance Sheet Detailed'!B29:B30,'Balance Sheet Detailed'!B35:B36)/'Balance Sheet Detailed'!B26 -> 0.17652581 | D29: =SUM('Balance Sheet Detailed'!C29:C30,'Balance Sheet Detailed'!C35:C36)/'Balance Sheet Detailed'!C26 -> 0.14458613 | E29: =SUM('Balance Sheet Detailed'!D29:D30,'Balance Sheet Detailed'!D35:D36)/'Balance Sheet Detailed'!D26 -> 0.1349421 | F29: =((E29/C29)^(1/3))-1 -> -0.085648711
B30: Times interest earned | C30: =IF('Profit and loss'!B11>0,SUM('Profit and loss'!B7:B10)/'Profit and loss'!B11,"") -> 20.068801 | D30: =IF('Profit and loss'!C11>0,SUM('Profit and loss'!C7:C10)/'Profit and loss'!C11,"") -> 29.323907 | E30: =IF('Profit and loss'!D11>0,SUM('Profit and loss'!D7:D10)/'Profit and loss'!D11,"") -> 28.969709 | F30: =((E30/C30)^(1/3))-1 -> 0.13016253
B31: Interest coverage ratio | C31: =SUM('Profit and loss'!B7:B8)/'Profit and loss'!B11 -> 8.1152091 | D31: =SUM('Profit and loss'!C7:C8)/'Profit and loss'!C11 -> 12.68155 | E31: =SUM('Profit and loss'!D7:D8)/'Profit and loss'!D11 -> 12.236778 | F31: =((E31/C31)^(1/3))-1 -> 0.14671579
B32: Net income to liabilities | C32: ='Profit and loss'!B14/'Balance Sheet Detailed'!B43 -> 0.080813421 | D32: ='Profit and loss'!C14/'Balance Sheet Detailed'!C43 -> 0.2086616 | E32: ='Profit and loss'!D14/'Balance Sheet Detailed'!D43 -> 0.17117588 | F32: =((E32/C32)^(1/3))-1 -> 0.28426021
A45: Master Table
A46: Year | B46: Metric | C46: Value
A47: ='Balance Sheet'!$B$4 -> 45016 | B47: Gross Profit Margin | C47: =B15 -> 0.31387936
A48: ='Balance Sheet'!$B$4 -> 45016 | B48: Operating Profit Margin | C48: =B16 -> 0.10449216
A49: ='Balance Sheet'!$B$4 -> 45016 | B49: Net Profit Margin | C49: =B17 -> 0.033419635
A50: ='Balance Sheet'!$B$4 -> 45016 | B50: ROE | C50: =B18 -> 0.05228092
A51: ='Balance Sheet'!$B$4 -> 45016 | B51: ROA | C51: =B19 -> 0.031553082
A52: ='Balance Sheet'!$B$4 -> 45016 | B52: EV/EBITDA | C52: =B20 -> 14.366736
A53: ='Balance Sheet'!$B$4 -> 45016 | B53: P/E Ratio | C53: =B21 -> 45.907721
A54: ='Balance Sheet'!$B$4 -> 45016 | B54: Current Ratio | C54: =C25 -> 1.218665
A55: ='Balance Sheet'!$B$4 -> 45016 | B55: Quick Ratio | C55: =C26 -> 0.63454402
A56: ='Balance Sheet'!$B$4 -> 45016 | B56: Cash Ratio | C56: =C27 -> 0.019902873
A57: ='Balance Sheet'!$B$4 -> 45016 | B57: Debt to total assets | C57: =C28 -> 0.10661075
A58: ='Balance Sheet'!$B$4 -> 45016 | B58: Debt to Equity | C58: =C29 -> 0.17652581
...

Sheet Balance Sheet Detailed
A1: Assets | B1: As at 31.03.2023 | C1: As at 31.03.2024 | D1: As at 31.03.2025
A2: Non-Current Assets
A3: Property, Plant and Equipment | B3: 9414.12 | C3: 11193.96 | D3: 12257.95
A4: Capital Work-in-Progress | B4: 3045.22 | C4: 2362.51 | D4: 1166.47
A5: Right of Use Assets | B5: 609.98 | C5: 758.14 | D5: 850.22
A6: Other Intangible Assets Financial Assets | B6: 25.94 | C6: 25.12 | D6: 20.56
A7: - Investments | B7: 1130.92 | C7: 1141.64 | D7: 1155.67
A8: - Loans | B8: 1.19 | C8: 4.09 | D8: 7.61
A9: - Other Financial Assets | B9: 24.08 | C9: 25.8 | D9: 28.71
A10: Non Current Tax Asset (Net) | B10: 263.24 | C10: 343.54 | D10: 329.29
A11: Other Non-current Assets Current Assets | B11: 550.41 | C11: 358.16 | D11: 264.82
A12: Current Assets
A13: Inventories | B13: 4042.68 | C13: 4360.72 | D13: 5539.34
A14: Financial Assets - Investments | B14: 1974.84 | C14: 2261.98 | D14: 3403.33
A15: - Trade Receivables | B15: 2442.36 | C15: 2841.86 | D15: 3302.13
A16: - Cash and Cash Equivalents | B16: 146.31 | C16: 235.55 | D16: 243.61
A17: - Bank Balances other than Cash and Cash Equivalents | B17: 9.98 | C17: 4.79 | D17: 5.85
A18: - Loans | B18: 2.95 | C18: 5.8 | D18: 4.99
A19: - Other Financial Assets | B19: 101.15 | C19: 187.55 | D19: 191.2
A20: Other Current Assets | B20: 238.38 | C20: 303.58 | D20: 324.35
A21: TOTAL ASSETS | B21: 24023.75 | C21: 26414.79 | D21: 29096.1
A23: Equity
A24: EQUITy AND LIABILITIES EQUITy Share Capital | B24: 4.24 | C24: 4.24 | D24: 4.24
A25: Other Equity | B25: 14504.63 | C25: 16436.41 | D25: 18171.63
A26: Total Equity | B26: 14508.87 | C26: 16440.65 | D26: 18175.87
A27: Liabilities
A28: Non-current Liabilities
A29: Borrowings | B29: 823.58 | C29: 724.11 | D29: 374.43
A30: Lease Liability | B30: 508.62 | C30: 655.19 | D30: 755.31
A31: Provisions | B31: 215.02 | C31: 259.45 | D31: 284.88
A32: Deferred Tax Liabilities (Net) | B32: 381.67 | C32: 457.84 | D32: 456.5
A33: Other Non-current Liabilities Current Liabilities Financial Liabilities | B33: 234.79 | C33: 336.55 | D33: 242.6
A34: Current Liabilities
A35: Borrowings | B35: 1153.5 | C35: 906.7 | D35: 1212.11
A36: Lease Liability | B36: 75.49 | C36: 91.09 | D36: 110.84
A37: Trade Payables
A38: (A) total outstanding dues of micro enterprises and small enterprises; | B38: 55.95 | C38: 32.77 | D38: 28.55
A39: (B) total outstanding dues of creditors other than micro enterprises and small enterprises | B39: 2701.5 | C39: 2911.64 | D39: 3978.19
A40: - Other Financial Liabilities | B40: 722.61 | C40: 507.94 | D40: 388.32
A41: Other Current Liabilities | B41: 2409.21 | C41: 2645.07 | D41: 2746.5
...
